<mujoco>
<option gravity="0 0 -9.80665" integrator = "RK4"/>
	<worldbody>
    <light diffuse=".5 .5 .5" pos="0 0 3" dir="0 0 -1"/>
	<geom type="plane" size="2.5 2.5 0.1" rgba=".9 .9 .9 1" pos="0 0 0"/>
		<body name="body0" pos="0 0 0">
		<joint name="joint1" type="hinge" axis="0 0 1" pos="0 0 0"/>
		<geom type="cylinder" size=".15 0.6" pos="0 0 0.6" rgba="0.9 0 0 0.7"/>
			<body name="body1" pos="0 0 1.2" xyaxes="1 0 0 0 0 1">
			<joint name="joint2" type="hinge" axis="0 0 1" pos="0 0 0"/>
			<site name="body1sensor" pos="0 0 0.0" rgba="1 0 0 1" size="0.0005 0.0005 0.0005" type="sphere"/>
			<geom type="cylinder" size=".1 0.4" pos="0 0 0.4" rgba="0 0.9 0 0.7"/>
				<body name="body2" pos="0 0 0.8" xyaxes="1 0 0 0 0 1">
				<site name="body2sensor" pos="0 0 0.0" rgba="1 0 0 1" size="0.0005 0.0005 0.0005" type="sphere"/>
				<geom type="cylinder" size=".075 0.4" pos="0 0 0.4" rgba="0 0.9 0 .7"/>
					<body name="body3" pos="0 0 0.8" xyaxes="0 -1 0 1 0 0">
					<site name="body3sensor" pos="0 0 0.0" rgba="1 0 0 1" size="0.0005 0.0005 0.0005" type="sphere"/>
					</body>
				</body>
			</body>
		</body>
	</worldbody>
	<actuator>
		<motor name="joint1motor" joint="joint1" />
	</actuator>
	<sensor>
        <velocimeter name="body3vel" site="body3sensor"/>
		<gyro name="body3ang" site="body3sensor"/>
		<framelinvel name="spatial3vel" objtype="site" objname="body3sensor"/>
		<frameangvel name="spatial3ang" objtype="site" objname="body3sensor"/>
        <velocimeter name="body2vel" site="body2sensor"/>
		<gyro name="body2ang" site="body2sensor"/>
		<framelinvel name="spatial2vel" objtype="site" objname="body2sensor"/>
		<frameangvel name="spatial2ang" objtype="site" objname="body2sensor"/>
		<framelinvel name="spatial1vel" objtype="site" objname="body1sensor"/>
		<frameangvel name="spatial1ang" objtype="site" objname="body1sensor"/>
	</sensor>
	<keyframe>
	<key name="home" qpos="1.5707 0"/>
	</keyframe>
</mujoco>


			