<mujoco>
<option gravity="0 0 0"/>
	<worldbody>
    <light diffuse=".5 .5 .5" pos="0 0 3" dir="0 0 -1"/>
	<geom type="plane" size="2.5 2.5 0.1" rgba=".9 .9 .9 1" pos="0 0 0"/>
		<body name="body1" pos="0.0275 0 0.339" xyaxes="1 0 0 0 0 1">
		<geom type="cylinder" size=".02 0" fromto="-0.0275 0 0 -0.0275 -0.339 0" rgba="0.9 0 0 0.7"/>
		<geom type="cylinder" size=".02 0" fromto="-0.0275 0 0 0 0 0" rgba="0.9 0 0 0.7"/>
		<joint name="joint1" type="hinge" axis="0 1 0" pos="-0.0275 -0.339 0"/>
			<body name="body2" pos="0.250 0 0" xyaxes="1 0 0 0 1 0">
			<geom type="cylinder" size=".02 0" fromto="-0.250 0 0 0 0 0" rgba="0.9 0 0 0.7"/>
			<joint name="joint2" type="hinge" axis="0 0 1" pos="-0.250 0 0"/>
				<body name="body3" pos="0.070 0 0" xyaxes="1 0 0 0 0 1">
				<geom type="cylinder" size=".02 0" fromto="-0.070 0 0 0 0 0" rgba="0.9 0 0 0.7"/>
				<joint name="joint3" type="hinge" axis="0 1 0" pos="-0.070 0 0"/>
					<body name="body4" pos="0 0 0.250" xyaxes="1 0 0 0 0 -1">
					<geom type="cylinder" size=".02 0" fromto="0 0.250 0 0 0 0" rgba="0.9 0 0 0.7"/>
					<joint name="joint4" type="hinge" axis="0 -1 0" pos="0 0.250 0"/>
						<body name="body5" pos="0 0 0" xyaxes="1 0 0 0 0 1">
						<joint name="joint5" type="hinge" axis="0 1 0" pos="0 0 0"/>
						<inertial mass="1" pos="0 0 0" fullinertia="0.1 0.1 0.1 0 0 0"/>
							<body name="body6" pos="0 0 0.095" xyaxes="1 0 0 0 1 0">
							<geom type="cylinder" size=".02 0" fromto="0 0 0 0 0 -0.095" rgba="0.9 0 0 0.7"/>
							<joint name="joint6" type="hinge" axis="0 0 1" pos="0 0 -0.095"/>
							<site name="body6sensor" pos="0 0 0" rgba="1 0 0 1" size="0.0005 0.0005 0.0005" type="sphere"/>
							</body>
						</body>
					</body>
				</body>
			</body>
		</body>
	</worldbody>
	<sensor>
		<framelinvel name="spatial6vel" objtype="site" objname="body6sensor"/>
		<frameangvel name="spatial6ang" objtype="site" objname="body6sensor"/>
	</sensor>
	<keyframe>
	</keyframe>
</mujoco>


			